Can not use cuDNN on context None: cannot compile with cuDNN. We got this error:
b'In file included from /tmp/try_flags_0jadmjll.c:4:0:\n/home/quang/anaconda3/envs/wap_py3/include/cudnn.h:63:10: fatal error: driver_types.h: No such file or directory\n #include "driver_types.h"\n          ^~~~~~~~~~~~~~~~\ncompilation terminated.\n'
WARNING: Preallocating too much memory can prevent cudnn and cublas from working properly
ERROR (theano.gpuarray): Could not initialize pygpu, support disabled
Traceback (most recent call last):
  File "/home/quang/anaconda3/envs/wap_py3/lib/python3.5/site-packages/theano/gpuarray/__init__.py", line 164, in <module>
    use(config.device)
  File "/home/quang/anaconda3/envs/wap_py3/lib/python3.5/site-packages/theano/gpuarray/__init__.py", line 151, in use
    init_dev(device)
  File "/home/quang/anaconda3/envs/wap_py3/lib/python3.5/site-packages/theano/gpuarray/__init__.py", line 90, in init_dev
    pygpu.empty((gmem,), dtype='int8', context=context)
  File "pygpu/gpuarray.pyx", line 749, in pygpu.gpuarray.empty
  File "pygpu/gpuarray.pyx", line 676, in pygpu.gpuarray.pygpu_empty
  File "pygpu/gpuarray.pyx", line 290, in pygpu.gpuarray.array_empty
pygpu.gpuarray.GpuArrayException: b'cuMemAlloc: CUDA_ERROR_OUT_OF_MEMORY: out of memory'
{'dim_coverage': [128], 'input_channels': [1], 'dim_ConvBlock': [32, 64, 64, 128], 'maxImagesize': [500000], 'kernel_coverage': [5, 5], 'kernel_Convenc': [3, 3], 'use-dropout': [True], 'bn_model': ['./models/bn_params.npz'], 'model': ['./models/attention_maxlen[200]_dimWord256_dim256.npz'], 'decay-c': [0.0001], 'clip-c': [100.0], 'learning-rate': [0.0002], 'reload': [False], 'layersNum_block': [4, 4, 4, 4], 'dim_dec': [256], 'dim_target': [111], 'dim_word': [256], 'dim_attention': [128], 'maxlen': [200], 'optimizer': ['adam']}
('total words/phones', 111)
Loading data
('total ', 1226, 'batch data loaded')
('sentence', '505_em_51', 'length bigger than', 200, 'ignore')
('total ', 138, 'batch data loaded')
Building model
/home/quang/Documents/Study/TUAT/WAP/VGG/nmt.py:146: VisibleDeprecationWarning: using a non-integer number instead of an integer will result in an error in the future
  W = numpy.asarray(rng.uniform(low=-W_bound, high=W_bound, size=(nin, nout)), dtype=numpy.float32)
Buliding sampler
Building f_init... Traceback (most recent call last):
  File "./train_nmt.py", line 95, in <module>
    "reload": [False],
  File "./train_nmt.py", line 45, in main
    use_dropout=params["use-dropout"][0],
  File "/home/quang/Documents/Study/TUAT/WAP/VGG/nmt.py", line 1006, in train
    f_init, f_next = build_sampler(tparams, bn_tparams, model_options, trng, use_noise)
  File "/home/quang/Documents/Study/TUAT/WAP/VGG/nmt.py", line 715, in build_sampler
    f_init = theano.function([x], outs, name='f_init', profile=profile,allow_input_downcast=True)
  File "/home/quang/anaconda3/envs/wap_py3/lib/python3.5/site-packages/theano/compile/function.py", line 326, in function
    output_keys=output_keys)
  File "/home/quang/anaconda3/envs/wap_py3/lib/python3.5/site-packages/theano/compile/pfunc.py", line 486, in pfunc
    output_keys=output_keys)
  File "/home/quang/anaconda3/envs/wap_py3/lib/python3.5/site-packages/theano/compile/function_module.py", line 1795, in orig_function
    defaults)
  File "/home/quang/anaconda3/envs/wap_py3/lib/python3.5/site-packages/theano/compile/function_module.py", line 1661, in create
    input_storage=input_storage_lists, storage_map=storage_map)
  File "/home/quang/anaconda3/envs/wap_py3/lib/python3.5/site-packages/theano/gof/link.py", line 699, in make_thunk
    storage_map=storage_map)[:3]
  File "/home/quang/anaconda3/envs/wap_py3/lib/python3.5/site-packages/theano/gof/vm.py", line 1047, in make_all
    impl=impl))
  File "/home/quang/anaconda3/envs/wap_py3/lib/python3.5/site-packages/theano/gof/op.py", line 935, in make_thunk
    no_recycling)
  File "/home/quang/anaconda3/envs/wap_py3/lib/python3.5/site-packages/theano/gof/op.py", line 835, in make_c_thunk
    no_recycling=e_no_recycling)
  File "/home/quang/anaconda3/envs/wap_py3/lib/python3.5/site-packages/theano/gof/cc.py", line 563, in accept
    self.fetch_variables()
  File "/home/quang/anaconda3/envs/wap_py3/lib/python3.5/site-packages/theano/gof/cc.py", line 589, in fetch_variables
    params = node.run_params()
  File "/home/quang/anaconda3/envs/wap_py3/lib/python3.5/site-packages/theano/gof/graph.py", line 129, in run_params
    return self.op.get_params(self)
  File "/home/quang/anaconda3/envs/wap_py3/lib/python3.5/site-packages/theano/gpuarray/dnn.py", line 231, in get_params
    ptr = ctx.cudnn_handle.value
AttributeError: ('The following error happened while compiling the node', GpuDnnBatchNormInference{mode='spatial', inplace=True}(GpuContiguous.0, GpuContiguous.0, GpuContiguous.0, GpuContiguous.0, GpuContiguous.0, Constant{9.99999974738e-05}), '\n', "'pygpu.gpuarray.GpuContext' object has no attribute 'cudnn_handle'")
